Workbook

Sheet experiment_data
A1: user_id | B1: signup_date | C1: experiment_group | D1: region | E1: device_type | F1: traffic_source | G1: plan_type | H1: visited_landing_page | I1: started_trial | J1: completed_onboarding | K1: converted_to_paid | L1: revenue_30d | M1: support_tickets_30d | N1: refund_requested | O1: days_to_convert | P1: engagement_score | Q1: User_id_Duplicates | R1: Outlier/Normal
A2: USR-100001 | B2: 45732 | C2: Control | D2: North | E2: Desktop | F2: Email | G2: Basic | H2: 0 | I2: 0 | J2: 0 | K2: 0 | L2: 0 | M2: 0 | N2: 0 | P2: 45.7 | Q2: =COUNTIF($A2:$A1409,A2) -> 1 | R2: =IF(L2>$W8,"Outlier","Normal") -> Normal
A3: USR-100002 | B3: 45724 | C3: Control | D3: West | E3: Mobile | F3: Organic | G3: Free | H3: 1 | I3: 0 | J3: 0 | K3: 0 | L3: 0 | M3: 0 | N3: 0 | P3: 48.6 | Q3: =COUNTIF($A3:$A1410,A3) -> 1 | R3: =IF(L3>$T9,"Outlier","Normal") -> Normal | V3: Calculate quartiles
A4: USR-100003 | B4: 45771 | C4: Control | D4: East | E4: Mobile | F4: Paid Search | G4: Premium | H4: 1 | I4: 0 | J4: 0 | K4: 0 | L4: 0 | M4: 1 | N4: 0 | P4: 35.4 | Q4: =COUNTIF($A4:$A1411,A4) -> 1 | R4: =IF(L4>$T10,"Outlier","Normal") -> Normal | V4: Q1 | W4: =_xlfn.QUARTILE.INC(L2:L1401,1) -> 0
A5: USR-100004 | B5: 45781 | C5: Control | D5: South | E5: Mobile | F5: Email | G5: Basic | H5: 1 | I5: 0 | J5: 0 | K5: 0 | L5: 0 | M5: 0 | N5: 0 | P5: 64.6 | Q5: =COUNTIF($A5:$A1412,A5) -> 1 | R5: =IF(L5>$T11,"Outlier","Normal") -> Normal | V5: Q3 | W5: =_xlfn.QUARTILE.INC(L2:L1401,3) -> 0
A6: USR-100005 | B6: 45700 | C6: Control | D6: North | E6: Tablet | F6: Organic | G6: Free | H6: 0 | I6: 0 | J6: 0 | K6: 0 | L6: 0 | M6: 0 | N6: 0 | P6: 66.6 | Q6: =COUNTIF($A6:$A1413,A6) -> 1 | R6: =IF(L6>$T12,"Outlier","Normal") -> Normal | V6: IQR | W6: =W5-W4 -> 0
A7: USR-100006 | B7: 45685 | C7: Control | D7: East | E7: Mobile | F7: Organic | G7: Premium | H7: 1 | I7: 0 | J7: 0 | K7: 0 | L7: 0 | M7: 0 | N7: 0 | P7: 40.8 | Q7: =COUNTIF($A7:$A1414,A7) -> 1 | R7: =IF(L7>$T13,"Outlier","Normal") -> Normal | V7: Lower Bound | W7: =W4-(1.5*W6) -> 0
A8: USR-100007 | B8: 45755 | C8: Control | D8: East | E8: Mobile | F8: Paid Search | G8: Basic | H8: 1 | I8: 1 | J8: 0 | K8: 0 | L8: 0 | M8: 0 | N8: 0 | P8: 57.1 | Q8: =COUNTIF($A8:$A1415,A8) -> 1 | R8: =IF(L8>$T14,"Outlier","Normal") -> Normal | V8: Upper Bound | W8: =W5+(1.5*W7) -> 0
A9: USR-100008 | B9: 45794 | C9: Control | D9: South | E9: Mobile | F9: Paid Search | G9: Free | H9: 0 | I9: 0 | J9: 0 | K9: 0 | L9: 0 | M9: 0 | N9: 0 | P9: 36.4 | Q9: =COUNTIF($A9:$A1416,A9) -> 1 | R9: =IF(L9>$T15,"Outlier","Normal") -> Normal
A10: USR-100009 | B10: 45711 | C10: Control | D10: South | E10: Tablet | F10: Referral | G10: Basic | H10: 0 | I10: 0 | J10: 0 | K10: 0 | L10: 0 | M10: 0 | N10: 0 | P10: 55.4 | Q10: =COUNTIF($A10:$A1417,A10) -> 1 | R10: =IF(L10>$T16,"Outlier","Normal") -> Normal
A11: USR-100010 | B11: 45806 | C11: Control | D11: West | E11: Desktop | F11: Social | G11: Free | H11: 1 | I11: 0 | J11: 0 | K11: 0 | L11: 0 | M11: 0 | N11: 0 | P11: 57.3 | Q11: =COUNTIF($A11:$A1418,A11) -> 1 | R11: =IF(L11>$T17,"Outlier","Normal") -> Normal
A12: USR-100011 | B12: 45777 | C12: Control | D12: East | E12: Mobile | F12: Paid Search | G12: Basic | H12: 1 | I12: 1 | J12: 1 | K12: 0 | L12: 0 | M12: 0 | N12: 0 | P12: 63.6 | Q12: =COUNTIF($A12:$A1419,A12) -> 1 | R12: =IF(L12>$T18,"Outlier","Normal") -> Normal
A13: USR-100012 | B13: 45732 | C13: Control | D13: East | E13: Mobile | F13: Social | G13: Premium | H13: 1 | I13: 1 | J13: 1 | K13: 0 | L13: 0 | M13: 1 | N13: 0 | P13: 80.4 | Q13: =COUNTIF($A13:$A1420,A13) -> 1 | R13: =IF(L13>$T19,"Outlier","Normal") -> Normal
A14: USR-100013 | B14: 45695 | C14: Control | D14: South | E14: Desktop | F14: Email | G14: Basic | H14: 1 | I14: 0 | J14: 0 | K14: 0 | L14: 0 | M14: 0 | N14: 0 | P14: 62.4 | Q14: =COUNTIF($A14:$A1421,A14) -> 1 | R14: =IF(L14>$T20,"Outlier","Normal") -> Normal
A15: USR-100014 | B15: 45718 | C15: Control | D15: West | E15: Mobile | F15: Social | G15: Basic | H15: 1 | I15: 0 | J15: 0 | K15: 0 | L15: 0 | M15: 0 | N15: 0 | P15: 82.4 | Q15: =COUNTIF($A15:$A1422,A15) -> 1 | R15: =IF(L15>$T21,"Outlier","Normal") -> Normal
A16: USR-100015 | B16: 45807 | C16: Control | D16: South | E16: Mobile | F16: Organic | G16: Basic | H16: 0 | I16: 0 | J16: 0 | K16: 0 | L16: 0 | M16: 0 | N16: 0 | P16: 61.2 | Q16: =COUNTIF($A16:$A1423,A16) -> 1 | R16: =IF(L16>$T22,"Outlier","Normal") -> Normal
A17: USR-100016 | B17: 45741 | C17: Control | D17: South | E17: Mobile | F17: Social | G17: Basic | H17: 1 | I17: 0 | J17: 0 | K17: 0 | L17: 0 | M17: 0 | N17: 0 | P17: 68.9 | Q17: =COUNTIF($A17:$A1424,A17) -> 1 | R17: =IF(L17>$T23,"Outlier","Normal") -> Normal
A18: USR-100017 | B18: 45743 | C18: Control | D18: East | E18: Desktop | F18: Paid Search | G18: Free | H18: 1 | I18: 1 | J18: 1 | K18: 0 | L18: 0 | M18: 0 | N18: 0 | P18: 71.9 | Q18: =COUNTIF($A18:$A1425,A18) -> 1 | R18: =IF(L18>$T24,"Outlier","Normal") -> Normal
A19: USR-100018 | B19: 45805 | C19: Control | D19: South | E19: Desktop | F19: Paid Search | G19: Free | H19: 0 | I19: 0 | J19: 0 | K19: 0 | L19: 0 | M19: 0 | N19: 0 | P19: 50.5 | Q19: =COUNTIF($A19:$A1426,A19) -> 1 | R19: =IF(L19>$T25,"Outlier","Normal") -> Normal
A20: USR-100019 | B20: 45703 | C20: Control | D20: North | E20: Desktop | F20: Paid Search | G20: Basic | H20: 0 | I20: 0 | J20: 0 | K20: 0 | L20: 0 | M20: 0 | N20: 0 | P20: 49.3 | Q20: =COUNTIF($A20:$A1427,A20) -> 1 | R20: =IF(L20>$T26,"Outlier","Normal") -> Normal
... A60: USR-100059 | B60: 45761 | C60: Control | D60: North | E60: Mobile | F60: Social | G60: Free | H60: 0 | I60: 0 | J60: 0 | K60: 0 | L60: 0 | M60: 2 | N60: 0 | P60: 48.9 | Q60: =COUNTIF($A60:$A1467,A60) -> 1 | R60: =IF(L60>$T66,"Outlier","Normal") -> Normal
A61: USR-100060 | B61: 45658 | C61: Control | D61: West | E61: Mobile | F61: Social | G61: Free | H61: 1 | I61: 1 | J61: 1 | K61: 1 | L61: 240.42 | M61: 0 | N61: 0 | O61: 16 | P61: 56.5 | Q61: =COUNTIF($A61:$A1468,A61) -> 1 | R61: =IF(L61>$T67,"Outlier","Normal") -> Outlier
A62: USR-100061 | B62: 45749 | C62: Control | D62: South | E62: Mobile | F62: Referral | G62: Free | H62: 1 | I62: 0 | J62: 0 | K62: 0 | L62: 0 | M62: 0 | N62: 0 | P62: 53.7 | Q62: =COUNTIF($A62:$A1469,A62) -> 1 | R62: =IF(L62>$T68,"Outlier","Normal") -> Normal
A63: USR-100062 | B63: 45745 | C63: Control | D63: North | E63: Mobile | F63: Social | G63: Premium | H63: 0 | I63: 0 | J63: 0 | K63: 0 | L63: 0 | M63: 0 | N63: 0 | P63: 62.2 | Q63: =COUNTIF($A63:$A1470,A63) -> 1 | R63: =IF(L63>$T69,"Outlier","Normal") -> Normal
A64: USR-100063 | B64: 45792 | C64: Control | D64: South | E64: Desktop | F64: Organic | G64: Free | H64: 1 | I64: 0 | J64: 0 | K64: 0 | L64: 0 | M64: 0 | N64: 0 | P64: 50.2 | Q64: =COUNTIF($A64:$A1471,A64) -> 1 | R64: =IF(L64>$T70,"Outlier","Normal") -> Normal
A65: USR-100064 | B65: 45758 | C65: Control | D65: North | E65: Mobile | F65: Organic | G65: Basic | H65: 1 | I65: 0 | J65: 0 | K65: 0 | L65: 0 | M65: 0 | N65: 0 | P65: 74.3 | Q65: =COUNTIF($A65:$A1472,A65) -> 1 | R65: =IF(L65>$T71,"Outlier","Normal") -> Normal
A66: USR-100065 | B66: 45723 | C66: Control | D66: South | E66: Desktop | F66: Paid Search | G66: Free | H66: 1 | I66: 0 | J66: 0 | K66: 0 | L66: 0 | M66: 0 | N66: 0 | P66: 58 | Q66: =COUNTIF($A66:$A1473,A66) -> 1 | R66: =IF(L66>$T72,"Outlier","Normal") -> Normal
A67: USR-100066 | B67: 45807 | C67: Control | D67: South | E67: Mobile | F67: Organic | G67: Free | H67: 0 | I67: 0 | J67: 0 | K67: 0 | L67: 0 | M67: 0 | N67: 0 | P67: 46.7 | Q67: =COUNTIF($A67:$A1474,A67) -> 1 | R67: =IF(L67>$T73,"Outlier","Normal") -> Normal
A68: USR-100067 | B68: 45664 | C68: Control | D68: South | E68: Desktop | F68: Organic | G68: Premium | H68: 1 | I68: 0 | J68: 0 | K68: 0 | L68: 0 | M68: 1 | N68: 0 | P68: 49.6 | Q68: =COUNTIF($A68:$A1475,A68) -> 1 | R68: =IF(L68>$T74,"Outlier","Normal") -> Normal
A69: USR-100068 | B69: 45785 | C69: Control | D69: West | E69: Mobile | F69: Social | G69: Free | H69: 0 | I69: 0 | J69: 0 | K69: 0 | L69: 0 | M69: 0 | N69: 0 | P69: 60.4 | Q69: =COUNTIF($A69:$A1476,A69) -> 1 | R69: =IF(L69>$T75,"Outlier","Normal") -> Normal
A70: USR-100069 | B70: 45735 | C70: Control | D70: East | E70: Desktop | F70: Email | G70: Free | H70: 1 | I70: 1 | J70: 1 | K70: 0 | L70: 0 | M70: 0 | N70: 0 | P70: 55.3 | Q70: =COUNTIF($A70:$A1477,A70) -> 1 | R70: =IF(L70>$T76,"Outlier","Normal") -> Normal
A71: USR-100070 | B71: 45793 | C71: Control | D71: North | E71: Desktop | F71: Organic | G71: Free | H71: 0 | I71: 0 | J71: 0 | K71: 0 | L71: 0 | M71: 0 | N71: 0 | P71: 56.2 | Q71: =COUNTIF($A71:$A1478,A71) -> 1 | R71: =IF(L71>$T77,"Outlier","Normal") -> Normal
A72: USR-100071 | B72: 45724 | C72: Control | D72: West | E72: Mobile | F72: Email | G72: Free | H72: 0 | I72: 0 | J72: 0 | K72: 0 | L72: 0 | M72: 0 | N72: 0 | P72: 29.4 | Q72: =COUNTIF($A72:$A1479,A72) -> 1 | R72: =IF(L72>$T78,"Outlier","Normal") -> Normal
A73: USR-100072 | B73: 45724 | C73: Control | D73: East | E73: Mobile | F73: Email | G73: Free | H73: 1 | I73: 0 | J73: 0 | K73: 0 | L73: 0 | M73: 0 | N73: 0 | P73: 54.2 | Q73: =COUNTIF($A73:$A1480,A73) -> 1 | R73: =IF(L73>$T79,"Outlier","Normal") -> Normal
... A79: USR-100078 | B79: 45673 | C79: Control | D79: North | E79: Mobile | F79: Organic | G79: Free | H79: 0 | I79: 0 | J79: 0 | K79: 0 | L79: 0 | M79: 2 | N79: 0 | P79: 48.4 | Q79: =COUNTIF($A79:$A1486,A79) -> 1 | R79: =IF(L79>$T85,"Outlier","Normal") -> Normal
A80: USR-100079 | B80: 45708 | C80: Control | D80: West | E80: Desktop | F80: Organic | G80: Free | H80: 1 | I80: 1 | J80: 1 | K80: 1 | L80: 457.51 | M80: 0 | N80: 0 | O80: 7 | P80: 38 | Q80: =COUNTIF($A80:$A1487,A80) -> 1 | R80: =IF(L80>$T86,"Outlier","Normal") -> Outlier
A81: USR-100080 | B81: 45798 | C81: Control | D81: East | E81: Mobile | F81: Social | G81: Free | H81: 1 | I81: 0 | J81: 0 | K81: 0 | L81: 0 | M81: 0 | N81: 0 | P81: 44.2 | Q81: =COUNTIF($A81:$A1488,A81) -> 1 | R81: =IF(L81>$T87,"Outlier","Normal") -> Normal
A82: USR-100081 | B82: 45785 | C82: Control | D82: South | E82: Mobile | F82: Organic | G82: Free | H82: 1 | I82: 1 | J82: 1 | K82: 0 | L82: 0 | M82: 0 | N82: 0 | P82: 81.2 | Q82: =COUNTIF($A82:$A1489,A82) -> 1 | R82: =IF(L82>$T88,"Outlier","Normal") -> Normal
A83: USR-100082 | B83: 45724 | C83: Control | D83: South | E83: Mobile | F83: Referral | G83: Free | H83: 1 | I83: 1 | J83: 0 | K83: 0 | L83: 0 | M83: 0 | N83: 0 | P83: 63.8 | Q83: =COUNTIF($A83:$A1490,A83) -> 1 | R83: =IF(L83>$T89,"Outlier","Normal") -> Normal
A84: USR-100083 | B84: 45748 | C84: Control | D84: South | E84: Desktop | F84: Email | G84: Free | H84: 0 | I84: 0 | J84: 0 | K84: 0 | L84: 0 | M84: 0 | N84: 0 | P84: 64.7 | Q84: =COUNTIF($A84:$A1491,A84) -> 1 | R84: =IF(L84>$T90,"Outlier","Normal") -> Normal
...

Sheet Data_Cleaning_Summary
E1: Segment distribution across groups | K1: Traffice Type Distribution
A2: Missing Values Summary | E2: Region Distribution | K2: Count of user_id | L2: Column Labels
A3: Column | B3: Count | C3: Action Taken | E3: Count of user_id | F3: Column Labels | K3: Row Labels | L3: Control | M3: Treatment | N3: Grand Total
A4: device_type | B4: =COUNTBLANK(experiment_data!E2:E1409) -> 8 | C4: Documented | E4: Row Labels | F4: Control | G4: Treatment | H4: Grand Total | K4: Email | L4: 73 | M4: 56 | N4: 129
A5: traffic_source | B5: =COUNTBLANK(experiment_data!F2:F1409) -> 8 | C5: Documented | E5: East | F5: 157 | G5: 170 | H5: 327 | K5: Organic | L5: 246 | M5: 237 | N5: 483
A6: engagement_score | B6: =COUNTBLANK(experiment_data!P2:P1409) -> 22 | C6: Documented | E6: North | F6: 201 | G6: 180 | H6: 381 | K6: Paid Search | L6: 155 | M6: 176 | N6: 331
E7: South | F7: 184 | G7: 183 | H7: 367 | K7: Referral | L7: 81 | M7: 91 | N7: 172
E8: West | F8: 148 | G8: 177 | H8: 325 | K8: Social | L8: 129 | M8: 132 | N8: 261
A9: Check Group Counts | E9: Grand Total | F9: 690 | G9: 710 | H9: 1400 | K9: Unknown | L9: 6 | M9: 18 | N9: 24
A10: Control group | B10: =COUNTIF(experiment_data!C2:C1409, "Control") -> 690 | C10: No Action | K10: Grand Total | L10: 690 | M10: 710 | N10: 1400
A11: Treatment group | B11: =COUNTIF(experiment_data!C2:C1409,"Treatment") -> 710 | C11: No Action
E12: Device Type Distribution
E13: Count of user_id | F13: Column Labels
A14: Check Duplicate User IDs | E14: Row Labels | F14: Control | G14: Treatment | H14: Grand Total
A15: Duplicate User ID's removed | B15: 8 | C15: Removed | E15: Desktop | F15: 200 | G15: 213 | H15: 413
E16: Mobile | F16: 426 | G16: 432 | H16: 858
A17: Validate Binary Columns | E17: Tablet | F17: 55 | G17: 56 | H17: 111
A18: Column | B18: Invalid Count | E18: Unknown | F18: 9 | G18: 9 | H18: 18
A19: visited_landing_page | B19: =COUNTIFS(experiment_data!H2:H1401,"<>0",experiment_data!H2:H1401,"<>1") -> 0 | C19: No Action | E19: Grand Total | F19: 690 | G19: 710 | H19: 1400
A20: started_trial | B20: =COUNTIFS(experiment_data!I2:I1401,"<>0",experiment_data!I2:I1401,"<>1") -> 0 | C20: No Action
A21: completed_onboarding | B21: =COUNTIFS(experiment_data!J2:J1401,"<>0",experiment_data!J2:J1401,"<>1") -> 0 | C21: No Action
A22: converted_to_paid | B22: =COUNTIFS(experiment_data!K2:K1401,"<>0",experiment_data!K2:K1401,"<>1") -> 0 | C22: No Action
A23: refund_requested | B23: =COUNTIFS(experiment_data!N2:N1401,"<>0",experiment_data!N2:N1401,"<>1") -> 0 | C23: No Action
A26: Outliers in revenue
A27: No. of Outliers | B27: =COUNTIF(experiment_data!R2:R1401,"Outlier") -> 72 | C27: Retained

Sheet Hypothesis_Test
A1: Hypothesis Testing Table
A2: Metric | B2: Control | C2: Treatment
A3: Total Users | B3: =COUNTIF(experiment_data!C:C,"Control") -> 690 | C3: =COUNTIF(experiment_data!C:C,"Treatment") -> 710
A4: Converted Users | B4: =COUNTIFS(experiment_data!C:C,"Control",experiment_data!K:K,1) -> 22 | C4: =COUNTIFS(experiment_data!C:C,"Treatment",experiment_data!K:K,1) -> 50
A5: Conversion Rate | B5: =B4/B3 -> 0.031884058 | C5: =C4/C3 -> 0.070422535
A8: Pooled Conversion Rate: | B8: =(B4+C4)/(B3+C3) -> 0.051428571
A10: Calculate Standard Error | D10: Calculate Z Statistic
A11: Formula | B11: Value | D11: Formula | E11: Value
A12: '=SQRT( PooledRate*(1-PooledRate)* ((1/ControlUsers)+(1/TreatmentUsers)) )' | B12: =SQRT(B8*(1-B8)* ((1/B3)+(1/C3)) ) -> 0.011807217 | D12: =(TreatmentRate-ControlRate)/StandardError' | E12: =(C5-B5)/B12 -> 3.2639763
A15: Calculate P-value: One-Tailed Test | D15: Apply Decision Rule
A16: Formula | B16: Value | D16: ∝ | E16: 0.05
A17: =1-NORM.S.DIST(Z_Statistic,TRUE)' | B17: =1-_xlfn.NORM.S.DIST(E12,TRUE) -> 0.00054930169 | D17: Formula | E17: =IF(P_Value<0.05,"Reject H0","Fail to Reject H0")'
D18: Decision | E18: =IF(B17<0.05,"Reject H0","Fail to Reject H0") -> Reject H0

Sheet GuardRail Metric
B2: Control | C2: Treatment
A3: Refund Rate | B3: =COUNTIFS(experiment_data!C:C,"Control",experiment_data!N:N,1)/COUNTIF(experiment_data!C:C,"Control") -> 0 | C3: =COUNTIFS(experiment_data!C:C,"Treatment",experiment_data!N:N,1)/COUNTIF(experiment_data!C:C,"Treatment") -> 0.0042253521
A4: Support Ticket Rate | B4: =COUNTIFS(experiment_data!C:C,"Control",experiment_data!M:M,1)/COUNTIF(experiment_data!C:C,"Control") -> 0.092753623 | C4: =COUNTIFS(experiment_data!C:C,"Treatment",experiment_data!M:M,1)/COUNTIF(experiment_data!C:C,"Treatment") -> 0.16056338
A5: Average Days to Convert | B5: =AVERAGEIFS(experiment_data!O:O,experiment_data!C:C,"Control",experiment_data!K:K,1) -> 8.8636364 | C5: =AVERAGEIFS(experiment_data!O:O,experiment_data!C:C,"Treatment",experiment_data!K:K,1) -> 6.4
A6: Average Engagement Score | B6: =AVERAGEIFS(experiment_data!P:P,experiment_data!C:C,"Control") -> 57.029532 | C6: =AVERAGEIFS(experiment_data!P:P,experiment_data!C:C,"Treatment") -> 62.940028
A7: ARPU | B7: =SUMIFS(experiment_data!L:L,experiment_data!C:C,"Control")/COUNTIF(experiment_data!C:C,"Control") -> 51.974319 | C7: =SUMIFS(experiment_data!L:L,experiment_data!C:C,"Treatment")/COUNTIF(experiment_data!C:C,"Treatment") -> 54.254521

Sheet business_context
A1: Item | B1: Description
A2: Business context | B2: A subscription product tested a new onboarding and activation campaign against the existing experience.
A3: Control | B3: Existing onboarding experience.
A4: Treatment | B4: New campaign experience.
A5: Primary decision | B5: Decide whether to launch, reject, continue testing, or launch only for selected segments.
A6: visited_landing_page | B6: 1 if the user visited the landing page after signup; otherwise 0.
A7: started_trial | B7: 1 if the user started a trial; otherwise 0.
A8: completed_onboarding | B8: 1 if the user completed onboarding; otherwise 0.
A9: converted_to_paid | B9: 1 if the user became a paid customer; otherwise 0.
A10: revenue_30d | B10: Revenue generated within 30 days of signup.
A11: support_tickets_30d | B11: Number of support tickets raised within 30 days.
A12: refund_requested | B12: 1 if the user requested a refund; otherwise 0.
... A14: Guardrail caution | B14: A better conversion rate may still be risky if refunds, support tickets, or low-quality revenue increase.
